
## 总结一下 Promise, Generator, Async & await 的错误捕捉


### Promise

*Promise.prototype.catch*

`Promise.prototype.catch`的方法区别于普通的`try...catch...`，这里需要把它理解成`promise.then(null, reject)` 的别名，即具有一下特点
* 可以把普通的对象进行包装，成promise，并在后续继续使用.then
* catch可以捕捉前面所有抛出的错误，并可以向后继续抛错
* 在没有写catch回调的情况下Promise无法捕捉其内部的错误
* 如果前面没有错误进行捕捉，会自动跳过catch，继续后面的.then

由于可以继续向下的冒泡的特性，某些场景下无法判断是否是最后一个错误，可以用`Promise.prototype.done`作为最后一个步骤处理错误并抛出一个可以被外界捕捉的错误


### Generator

> Generator的错误捕捉分为内部捕捉和外部捕捉

**内部捕捉**
除了内部的方法被内部的catch捕捉以外。
`Generator.prototype.throw`可以用来在*外部*抛出错误，然后在*内部*捕捉，可以抛出`Error`的实例
*必须使用一次`next`，同时只能被捕捉一次，捕捉以后`Generator`的状态就变了，就不会再被内部捕捉了*

```js
function* foo(){
    try {
        yield fetch()
        yield todo()
    }catch(error) {
        console.log(error)
    }
}

const g = foo()
g.next() 
g.throw('this can be catched inner generator')
g.throw('this cannot be catched inner')
```


**外部捕捉**
`Generator` 的外部捕捉和其他的没有太大区别，在执行`next`的时候也是可以被外部的`catch`捕捉的

```js
function* foo(){
    try {
        yield fetch()
        yield todo()
    }catch(error) {
        console.log(error)
    }
}

const g = foo()
g.next() 

try {
    g.next()
}catch( error ) {
    console.log(error)
}
```